{
    "summary": "This code defines a class `mClass` with three methods and is decorated for reloading. It includes a loop test case, an exception-raising function, and a main execution function with asynchronous task definition. However, the exception handling in the methods needs improvement.",
    "details": [
        {
            "comment": "This code defines a class `mClass` with three methods: `forLoopInFunction`, `someMethod`, and `someOtherMethod`. The class is decorated with `@reloading`, suggesting it will be reloaded when changes are made. Inside the `forLoopInFunction` method, there's an unfinished loop that attempts to raise exceptions but doesn't seem to achieve its goal correctly. The `someMethod` and `someOtherMethod` methods both contain inner decorators (`@reloading`) with incomplete exception handling and return statements.",
            "location": "\"/media/root/Toshiba XG3/works/pyjom_doc/src/tests/skipexception_code_and_continue_resurrection_time_travel_debugging/test_method_in_class/test.py\":0-34",
            "content": "from reloading import reloading\nimport asyncio\n# you had better decorate this.\n# @reloading\nclass mClass:\n    someValue = 2\n    def forLoopInFunction(self):\n        val='shit'\n        # for i in reloading(range(3)): # still not solved!\n        for i in range(3): # still not solved!\n            # raise Exception('shit')\n            # return in primary function, not here!\n            if True:\n                val = 'value'# value not assigned correctly.\n                # break # break outside loop? fuck?\n                # what the fuck?\n        return val\n    @reloading\n    def someMethod(self):\n        @reloading\n        def someInnerMethod():\n            # raise Exception(\"inner exception\")\n            return \"inside function return\"\n        # raise Exception(\"exception\")\n        val = someInnerMethod()\n        return val\n    @reloading\n    async def someOtherMethod(self):\n        @reloading\n        async def asyncInside():\n            # raise Exception(\"inner async exception\")\n            return \"async inside return\""
        },
        {
            "comment": "The code raises an exception, defines a function to run asynchronously, includes a non-reentrant for loop test case, and a main function that executes various methods.",
            "location": "\"/media/root/Toshiba XG3/works/pyjom_doc/src/tests/skipexception_code_and_continue_resurrection_time_travel_debugging/test_method_in_class/test.py\":35-67",
            "content": "        # raise Exception('async exception')\n        val = await asyncInside()\n        return val\n    @reloading\n    def runAsync(self):\n        loop = asyncio.get_event_loop()\n        val = loop.run_until_complete(self.someOtherMethod())\n        print(\"value from async func:\", val)\n        return val\ndef forLoop():\n    val = None\n    for i in reloading(range(3)): # multiple reloading for for-loop is not supported.\n        val = 'abcd'\n    return val\n@reloading\ndef main():\n    MClass = mClass()\n    print(MClass)\n    val = MClass.someMethod()\n    print(\"return value:\", val)\n    val = MClass.runAsync()\n    print(\"return async value:\", val)\n    val = MClass.forLoopInFunction()\n    print(\"return for loop value in class:\", val)\n    val = forLoop()\n    print(\"return for loop value:\", val)\n    print(\"success!\")\nmain()"
        }
    ]
}