{
    "summary": "This code tests error handling and function execution preservation by setting an exception hook, enabling autoreload, and creating a temp file for dynamic environments. It runs a progress bar then calls anotherFunction() and allows user input to continue or not upon exception.",
    "details": [
        {
            "comment": "This code is importing necessary modules and defining functions for handling exceptions. It sets a custom exception hook, enables autoreload for some functions, and creates a temporary file. The purpose seems to be testing error handling and context preservation in a dynamic environment.",
            "location": "\"/media/root/Toshiba XG3/works/pyjom_doc/src/tests/skipexception_code_and_continue_resurrection_time_travel_debugging/hook_error_handler_to_see_if_context_preserved.py\":0-37",
            "content": "# \n# import sys\n# i can assure that not a single 'reloading' decorator has been added to my code manually yet.\n# from basic import on_error_resume_next, err\n# on_error_resume_next()\nimport tempfile\n# def customExceptHook(a,b,c):\n#     print('ERROR INFO:', a,b,c)\n#     # <class 'AttributeError'> '_io.BufferedRandom' object has no attribute 'path' <traceback object at 0x7fd6c4325080>\n#     # it is a traceback object.\n#     print(\"context preserved! please take action!\")\n#     # preserved my ass.\n#     # this won't preserve context in any degree.\n#     while True:\n#         i = input('exit? (y for exit)\\n').lower()\n#         if i == 'y':\n#             break\n#     print('closing program now!')\n# sys.excepthook=customExceptHook\nimport os\n# add reloading to all these files? are you sure?\n# no support for block statements yet.\nfrom reloadr import autoreload\n@autoreload\ndef makeTrouble():\n    return 'success!'\ndef someFunction():\n    with tempfile.NamedTemporaryFile('w+',suffix='123') as f: # no such file now. wtf?\n        # print('LOCATION:',dir(f))"
        },
        {
            "comment": "This code checks if a file still exists after writing content, despite the exception being caught and handled. It attempts to run `maketrouble()` within a try-except block and provides a remedy input prompt for error handling.",
            "location": "\"/media/root/Toshiba XG3/works/pyjom_doc/src/tests/skipexception_code_and_continue_resurrection_time_travel_debugging/hook_error_handler_to_see_if_context_preserved.py\":38-62",
            "content": "        # /tmp/tmp7c5ffugz123\n        # still exist?\n        f.write('abcdefg')\n        f.flush() # write to disk.\n        print('LOCATION:',os.path.abspath(f.name))\n        print('has file?', os.path.exists(f.name)) # debugpy is nice.\n        # breakpoint() # we have the content here.\n        # this exception is caught, handled, but still recognized by the damn debugger.\n        try: # this must be directly in that context.\n            maketrouble() # no content here! it fucking triggered the alarm.\n        except:\n            mCode=None\n            while True:\n                try:\n                    mCode = input(\"remedy>>> \")\n                    if mCode == 'return':\n                        return\n                    elif mCode.startswith('return '):\n                        val = eval(mCode.replace('return ',''))\n                        return val\n                    else:\n                        exec(mCode)\n                except:\n                    import traceback\n                    traceback.print_exc()"
        },
        {
            "comment": "This code aims to test the error handling and function execution preservation. The main function runs a progress bar, then calls anotherFunction(). If an exception occurs in anotherFunction(), it prints the exception details and asks for user input to continue or not. It doesn't actually restart the function if an exception is raised.",
            "location": "\"/media/root/Toshiba XG3/works/pyjom_doc/src/tests/skipexception_code_and_continue_resurrection_time_travel_debugging/hook_error_handler_to_see_if_context_preserved.py\":63-103",
            "content": "                    print('trouble while executing code:', mCode)\n        print(\"won't have problem.\")\n    return 'myValue'\nfrom reloading import reloading\n@reloading\ndef anotherFunction():\n    # raise Exception('but just another shit!')\n    # it does not hook the function.\n    return 'yes please'\ndef mFunction():\n    while True:\n        try:\n            val= anotherFunction()\n            return val\n        except:\n            import traceback\n            traceback.print_exc()\n            print('please modify your code')\n            while True:\n                i = input('done? (y for done)\\n').lower()\n                if i == 'y':\n                    break\nimport progressbar\nimport time\ndef main():\n    print('please wait...')\n    for _ in progressbar.progressbar(range(5)):\n        time.sleep(1)\n    val = anotherFunction()\n    # val = mFunction()\n    print('value returned:', val) # it cannot restart the function actually raises the exception!\nif __name__ == \"__main__\":\n    main()"
        }
    ]
}